File: G_Tensile_Test/btrdata.csv
Engineering Stress (MPa),Engineering Strain,True Stress (MPa),True Strain,Tangent Modulus (MPa),%Difference in True and Engineering Stress
0.0,0.0,0.0,0.0,0,0
10.992900959573111,0.00014554035859992064,10.99450087032082,0.000145529768629436,75531.6330488903,0.014554035859985244
18.09066073659968,0.00016028846708199235,18.09356046087765,0.00016027562225816378,112863.14646296896,0.0160288467082009
22.832022408751758,0.00015731297627081858,22.83561418215116,0.00015730060388215208,145137.5655714873,0.015731297627084247
27.572785459556812,0.00016552791239499574,27.57734952517285,0.00016551421416181742,166574.83961835064,0.016552791239505923
32.01532283804352,0.00018422177305854465,32.02122075758178,0.00018420480631144246,173786.85649643175,0.0184221773058459
36.29224787949381,0.00022063919910197412,36.30025537199955,0.00022061486185365759,164486.85468043422,0.022063919910193158
40.63279514598204,0.00022464965798371482,40.6419232895145,0.00022462442802774707,180871.83176983768,0.022464965798365065
45.120210418578125,0.0002928919282800159,45.133425764012024,0.00029284904381272735,154050.71311982855,0.02928919282800515
49.72183142003529,0.0003040176824284683,49.736947735989716,0.00030397147841719816,163549.1430066218,0.030401768242855686
54.41799718048739,0.0003427637357606259,54.43664969649359,0.00034270500569139734,158762.41125604662,0.03427637357606981
59.294927880822314,0.0003562829595515297,59.31605365321409,0.0003562195058491582,166426.50536938297,0.035628295955157915
64.31281520146328,0.00032549294771576533,64.3337485692591,0.00032543998637820975,197585.89441889856,0.03254929477157082
69.47549406041463,0.00039004812306481863,69.5025928464719,0.0003899720740701394,178120.31375643646,0.03900481230648233
74.79310360674151,0.00037141917258172273,74.82088319939794,0.0003713502135553824,201371.1437857584,0.0371419172581649
80.1996084231008,0.00045046376526525336,80.23573544068388,0.0004503623369221737,178037.86809772736,0.045046376526544016
85.80829759941597,0.000475367366525474,85.84908806387183,0.00047525441525299506,180509.4409963408,0.047536736652545604
91.49400315340866,0.0004939315424815766,91.53919492751405,0.0004938095984503612,185236.20235656714,0.04939315424817194
97.22670048314235,0.000408547863627577,97.26642224391229,0.0004084644306725659,237981.17464095226,0.04085478636274735
103.11786410758243,0.00038351505244701886,103.15741136064386,0.000383441529346753,268875.66328789084,0.03835150524468679
109.08514617767948,0.00036747335257351574,109.12523206206137,0.00036740585077739727,296851.8544643484,0.036747335257361916
115.11099960519898,0.0003035001983931848,115.14593581641638,0.0003034541515244664,379278.169222389,0.030350019839304142
121.21863967425504,0.0002613258090881035,121.25031723334446,0.00026129166944633347,463860.1908370533,0.02613258090879611
127.47047266027445,0.000270963817830969,127.50501254620718,0.00027092711376575085,470433.5570728942,0.027096381783084558
133.7892015818233,0.0002981313735930193,133.8290883402628,0.00029808694126595887,448759.21634621266,0.029813137359305963
140.1745645420623,0.00027478022443864906,140.21308174036778,0.00027474247926710806,510133.37960701564,0.02747802244387391
146.76418833005468,0.0002844829059684131,146.80594023284291,0.0002844424483794162,515898.0917691775,0.028448290596845068
153.34902314727086,0.000258738456738416,153.38870043686234,0.00025870498971669804,592679.6699661325,0.025873845673849597
160.03648411166674,0.0002931506533409751,160.08339891154247,0.00029310769308391494,545918.9065000035,0.029315065334102976
166.83094864184235,0.00030337081890602265,166.8815602833507,0.0003033248112837644,549924.1794034342,0.030337081890599523
173.69586342179537,0.0003518843961216676,173.75698428580438,0.0003518224993274614,493616.2709577445,0.0351884396121682
180.69786249021593,0.00035634739494487386,180.7622537027864,0.00035628391829127076,507083.43895195157,0.03563473949448126
187.677974465636,0.00039625799931495003,187.75234336431322,0.00039617950984788844,473625.70544971526,0.0396257999314876
194.7869770998363,0.0004581610817006874,194.87622091196556,0.00045805615795908167,425149.54866264464,0.04581610817006897
201.92852976978077,0.00047497905849716316,202.02444159273455,0.00047486629165075764,425131.4371810074,0.0474979058497232
209.14846442235063,0.0004972954091477911,209.25247299353816,0.0004971717987646864,420571.8785555767,0.04972954091477425
216.44659398837493,0.0005065452794291703,216.55623398880823,0.000506417028677052,427299.59744623466,0.050654527942902455
223.77484169092116,0.0005398576995208042,223.89564826216707,0.0005397120287782311,414507.0856441452,0.05398576995208694
231.18446448282788,0.0005489135853548525,231.3113647761055,0.0005487629874004771,421167.32150721975,0.054891358535493144
238.60287952576894,0.000615215231170452,238.74967165145432,0.0006150260638619052,387836.4309541313,0.061521523117044556
246.1219377826777,0.0006564192912785,246.2834969706451,0.0006562039423698934,374946.22880949907,0.06564192912785666
253.65577450409097,0.0006635346543719414,253.824083900756,0.000663314612584711,382279.6184536661,0.06635346543719581
261.23918455580434,0.0007193574095615341,261.4271088988824,0.0007190987960365645,363156.3129585834,0.0719357409561669
268.9512981971269,0.0007242734909400446,269.146092492765,0.0007240113314710234,371339.4202072083,0.07242734909399913
276.68286703222765,0.0007976260644557414,276.9035564985609,0.0007973081298371467,346882.9309396022,0.07976260644556671
284.46008074503857,0.0007932919364192235,284.6857406333268,0.000792977446681569,358581.83814276493,0.07932919364193931
292.32821007492817,0.0008711722832851199,292.58287830916777,0.0008707930329570554,335557.28950946673,0.0871172283285035
300.18455404704827,0.0009062312416700299,300.4565906681925,0.0009058208620522576,331244.98499285814,0.09062312416701354
308.1696016087776,0.0009301001461666028,308.456230200278,0.0009296678710442899,331329.48411941994,0.09301001461665215
316.177845747704,0.000997436827879499,316.49321317521236,0.0009969397182962318,316990.3465664911,0.0997436827879498
324.1782329814508,0.001034953826953664,324.51374248429,0.001034418631478232,313229.6577284549,0.10349538269536229
332.2549444369425,0.001103519529011188,332.6215942567392,0.0011029110989042984,301086.6012807771,0.11035195290111832
340.3898344045977,0.0011442060711705877,340.7793105196882,0.0011435519663102426,297489.9740361975,0.11442060711705362
348.57317528752736,0.0011989293550695396,348.9910898997694,0.0011982112132139652,290737.04285713285,0.11989293550696162
356.8115145067144,0.0012425266813398492,357.25486233369827,0.001241755383901905,287166.0784957593,0.12425266813398722
338.18803026259104,0.001215747331866015,338.59918145805176,0.001215008909507856,278172.9569938814,0.1215747331865867
314.617875931205,0.0014782374545984826,315.0829558592927,0.0014771459371613303,212833.1107783094,0.14782374545985036
312.506613267935,0.0020164781648799976,313.13677602997035,0.0020144478017822833,154976.44294429172,0.20164781648798874
311.3198464474686,0.0030225825705652346,312.26083638921176,0.0030180237518278325,102997.9625632694,0.3022582570565251
311.0545823630705,0.004200746772295494,312.3612438959399,0.004191948267161429,74047.44899514498,0.42007467722954717
312.44020371225,0.005291654938294633,314.0935294591457,0.005277703328728052,59043.948888500585,0.529165493829457
312.2170301913143,0.006436831270835524,314.22671853453716,0.006416203344100757,48504.77153346097,0.6436831270835607
310.5577266450442,0.0075950744228793126,312.9164356915135,0.007566377059279582,40889.35925493025,0.7595074422879249
307.67330709826416,0.008721361011160889,310.3566370829659,0.00868354962766177,35278.129950649774,0.8721361011160925
305.9934259431903,0.00989603518850744,309.021547653776,0.009847390098026931,30920.810214837307,0.9896035188507282
308.02518420880915,0.011024522754172192,311.4210148609772,0.010964195683008639,27940.001674198378,1.1024522754172066
307.4357292511657,0.012194923847539077,311.18488455739634,0.012121164815436649,25210.139324749118,1.219492384753921
304.45964581062333,0.013395796099284768,308.5381251463629,0.01330686573775127,22727.999407730545,1.3395796099284822
303.9657831993321,0.014534050714045899,308.3836373076859,0.014429443756003447,20914.04448627495,1.4534050714045872
301.9826629181586,0.015558461554113862,306.68104856917967,0.015438669612290509,19409.545209070522,1.5558461554113727
302.0690888751345,0.016222383499113167,306.9693694780946,0.016092206602016972,18620.512139393562,1.6222383499113047
306.711210352101,0.016705577731128064,311.83499831764635,0.016567574396969875,18359.808639278348,1.6705577731128005
312.3395604982824,0.017255330333130984,317.7290827907853,0.017108147830029268,18101.047877279805,1.7255330333131182
318.54707679770524,0.017823972679393223,324.2248511916481,0.017666988323585826,17871.83376722666,1.7823972679393163
323.2965759787933,0.018439642688787228,329.2580493223506,0.018271693945695194,17532.69200684585,1.84396426887871
327.27890448984164,0.019240632280775532,333.5759575443857,0.019057871878596127,17009.779081784418,1.9240632280775387
330.7503470950428,0.02000080374674856,337.3656198764597,0.01980341528287759,16536.852782669364,2.0000803746748437
334.012272228787,0.020747264039285243,340.9421130330793,0.020534970870370536,16099.099697980899,2.074726403928525
337.21751540373543,0.021439907213033585,344.44742764460125,0.021213305559823058,15728.496959107022,2.1439907213033593
340.3032213784508,0.02216314702461093,347.8454117068101,0.021921114094628685,15354.463019198636,2.2163147024610885
343.2656487695143,0.022923837365067198,351.1346146749209,0.022665033919403086,14974.179204944297,2.2923837365067072
346.1575510831321,0.02354338706340782,354.30727229320365,0.02327051609851933,14702.963093239272,2.354338706340787
348.87734975948166,0.024334090731816502,357.3669628428046,0.024042733886228705,14336.979080271494,2.4334090731816547
351.50211729699197,0.02509258348622609,360.32221352085196,0.024782933863698207,14008.207544270592,2.5092583486226046
354.01801057701294,0.025768795634671667,363.14062834256504,0.0254423759691812,13738.244332252963,2.5768795634671706
356.3698441941164,0.02644500778311725,365.7940474974981,0.02610138349733656,13475.883505756665,2.6445007783117322
358.6895019138176,0.027075684456487458,368.4012656854908,0.0267156229306985,13247.66147612102,2.7075684456487488
360.86455516437934,0.027781781062098766,370.8900152290278,0.02740286926797612,12989.25199783854,2.7781781062098863
362.97057989086284,0.028459610878050934,373.30058135473735,0.02806215941081774,12753.884142906489,2.8459610878051085
365.0176778284991,0.02908297582994482,375.6334781302879,0.028668090947781697,12550.90538062011,2.9082975829944897
367.00959036070697,0.02972548826767141,377.91912963309704,0.02929225047479921,12346.629500443096,2.972548826767139
368.9874727050941,0.030383848420824165,380.1987321449486,0.029931401187667083,12144.198048730434,3.038384842082405
370.8607833829238,0.030997124146654956,382.35640112656995,0.030526415648444563,11964.361004210938,3.0997124146654857
372.72642422474473,0.03163724230081833,384.5184604198606,0.031147095867029465,11781.255163794847,3.1637242300818413
374.5653141751207,0.032246119463219265,386.6435920427899,0.031737126477620566,11615.826040784825,3.2246119463219305
376.36679029130795,0.03288552543671936,388.7438099469692,0.032356366413739096,11444.755262175737,3.288552543671936
378.1991328207009,0.033505332876633355,390.87082065951256,0.03295626014246718,11287.72945528493,3.35053328766333
379.9521580216138,0.03414055054956608,392.9239338789674,0.03357069581349676,11129.057730630033,3.4140550549565956
381.67899353859457,0.03474224146994089,394.93937729611645,0.03415235364318137,10986.020975901183,3.4742241469940933
383.3876833459938,0.03538934238594088,396.95552133847787,0.03477753219909815,10833.422084110334,3.538934238594084
385.08084641220466,0.0360583852490428,398.9662399241634,0.03542349866732305,10679.37024224974,3.605838524904276
386.7947741563903,0.0366434586206078,400.96827245785727,0.03598805008974282,10555.629537078195,3.664345862060764
388.43312595551475,0.03735089141279687,402.94144946421244,0.03667024367393818,10399.567754959466,3.7350891412796883
390.05894412018597,0.03795492235535102,404.8636010582778,0.03725235639737721,10276.900067619135,3.7954922355351
391.6911226366692,0.038614198169356566,406.81596126733933,0.03788732282314175,10143.707268470675,3.8614198169356655
393.2357527811509,0.03928476713387979,408.68392775787436,0.0385327526529835,10009.87867488257,3.9284767133879863
394.8413674753602,0.039956590892904986,410.6178824631683,0.03917897275611009,9881.758144323354,3.9956590892904984
396.33343118280663,0.04063933475543377,412.4401581674144,0.039835269232151915,9752.458635652592,4.063933475543376
397.8900337542287,0.0413121759154065,414.3277368236704,0.040481625480075056,9631.301787854849,4.131217591540653
399.3448706966574,0.04186374288243254,416.0629416849205,0.04101116979262004,9539.158307420146,4.186374288243244
400.8369344041039,0.04258277404542356,417.90568301089417,0.04170107110279647,9413.124048154456,4.25827740454237
402.2973834216609,0.043286306800647066,419.7113513855485,0.0423756415141056,9293.871738109272,4.328630680064706
403.7202315358582,0.043955587057303416,421.4659913199273,0.043016947422696176,9184.73073763164,4.3955587057303385
405.1333520531665,0.04463242999433647,423.2154380270503,0.0436650819089625,9077.107208919053,4.463242999433643
406.51373546555965,0.045287839684741364,424.92386434696925,0.04429229216324819,8976.222718844427,4.528783968474132
407.88195938184145,0.04595505122613771,426.6261957194514,0.04493039266026404,8875.671955509686,4.595505122613772
409.24831260641383,0.04666116139709498,428.34431417243053,0.045605251426526855,8770.641371817477,4.666116139709508
410.5604157714125,0.04734655050208737,429.9990352308917,0.046259870915818305,8671.390236830708,4.73465505020874
411.89702499780486,0.048035500510396144,431.68270475231753,0.046917459857942066,8574.846116335553,4.803550051039605
413.1874281389741,0.04870603556155446,433.31214970749824,0.04755705712110634,8483.290076376465,4.870603556155455
414.4297545032108,0.04940753351488288,434.90570648839287,0.04822575112300145,8387.987114927997,4.940753351488286
415.7074369407559,0.050103605329824434,436.5358782939084,0.0488888310443858,8296.956560395542,5.010360532982448
416.9235736210605,0.05084468018001215,438.12191938133105,0.049594298081374714,8199.944854505344,5.084468018001215
418.1413939239036,0.05152277791154716,439.68520009866967,0.050239378228938675,8115.6608954928015,5.152277791154725
419.24659858583857,0.05229149215414303,441.1696288064411,0.05097015973160648,8017.491590218886,5.229149215414303
420.46479302702363,0.05298200217723803,442.74185960663334,0.05162614105632785,7935.992898502852,5.298200217723805
421.66839607287505,0.053686145373030056,444.3061468836558,0.05229463098705848,7854.324298065656,5.368614537302996
422.7721041814425,0.05438760941299357,445.7656682543722,0.05296013338161233,7773.3165466257715,5.4387609412993525
423.9266951045066,0.05514621747284387,447.3046488252837,0.05367935208565269,7687.321352788421,5.514621747284387
425.0191790628175,0.05578192349823142,448.7275663945808,0.05428165211876788,7619.299450588018,5.5781923498231585
426.10885698356424,0.056552842109546954,450.20652389403523,0.05501157301776077,7534.702785726675,5.655284210954686
427.21293923047364,0.05731172147631661,451.6972482147291,0.05572957492994025,7454.198342428334,5.7311721476316535
428.2304084512361,0.05804045186167417,453.0850948586551,0.05641856697899053,7378.137052961321,5.804045186167414
429.2910906504865,0.058767317011961244,454.5193762651542,0.05710532294194846,7304.929210280444,5.876731701196116
430.3132366005226,0.05947237586860606,455.90498714886525,0.057771025586509775,7235.514477363832,5.947237586860595
431.3024583764726,0.060168922470656465,457.2534625559301,0.058428256248763036,7168.193157968098,6.016892247065648
432.3425629669192,0.060983351929161767,458.7082616382867,0.05919616858429532,7089.517864959737,6.098335192916186
433.27285795402196,0.06174202781574191,460.02400280162516,0.059910981650670894,7017.470486182405,6.174202781574187
434.2665693900746,0.06248184787142765,461.4003471143521,0.060607537314192265,6950.283709337293,6.248184787142779
435.207714389092,0.06322482187005077,462.7236446078143,0.06130657452328017,6883.494512386241,6.322482187005083
436.1170576290491,0.06394605740176147,464.0050240300836,0.06198469170359374,6820.077348772337,6.394605740176145
437.08457938116965,0.06465070929802727,465.34240746139216,0.06264677287653364,6760.708182895477,6.4650709298027245
437.97128725144245,0.06537821880224778,466.60506989846937,0.06332987114145604,6699.039760874985,6.5378218802247785
438.85313132327076,0.0661025065368011,467.8624233052629,0.06400948109881584,6638.978675928864,6.61025065368011
439.6709977386364,0.06688933051626315,469.0802964247913,0.06474724671186961,6573.111052916532,6.688933051626328
440.56574958325984,0.06765519603620591,470.3723117381533,0.06546483825730727,6511.92776601356,6.765519603620596
441.4064384374806,0.06836612190498154,471.5836848173411,0.06613049256427042,6456.508371953116,6.836612190498159
442.24899798341073,0.06908996876579092,472.8039674407869,0.06680779011591566,6401.05945745318,6.908996876579088
443.0485316200238,0.06983809759588155,473.990198211015,0.06750732636714758,6343.937576646575,6.983809759588144
443.8774351164751,0.07058080028758533,475.2066597165967,0.06820130521609712,6288.926072074449,7.058080028758537
444.6509661383271,0.07138644618457689,476.3930184034808,0.0689535538196271,6228.7869743317515,7.138644618457675
445.44208166224774,0.0721107339191302,477.5632370893776,0.06962935388024015,6177.19523090413,7.211073391913028
446.198215251202,0.07292563816474436,478.7375048463658,0.07038915851145604,6118.536998513576,7.292563816474427
446.95135573342105,0.07369001149663072,479.88720627585155,0.0711013245336439,6065.290894327743,7.3690011496630765
447.7200229568285,0.07446187968216395,481.0580974375355,0.07181995920926537,6012.741349908093,7.446187968216387
448.4424840950128,0.07522126774940736,482.17489626133306,0.07252647086400728,5961.644858060052,7.522126774940728
449.1799107668727,0.07602911801511858,483.33066321258775,0.07327752272578167,5907.998441827935,7.602911801511872
449.86140375662035,0.07676419019971581,484.3946501181047,0.07396042359727652,5860.302864997667,7.676419019971585
450.5791881655311,0.07749132665692222,485.4951672204771,0.0746354934570316,5814.575741623095,7.749132665692218
451.26610616123617,0.07831708317931013,486.6079513334691,0.07540156947659322,5762.039236421052,7.831708317931012
451.9541465719669,0.07909193574095616,487.7000748904955,0.07611988722549295,5714.288597667127,7.909193574095603
452.62853093321866,0.07985281599625596,488.7721937284846,0.07682475036401476,5668.285147945702,7.985281599625589
453.2870144149403,0.08064455741363115,489.8421450737794,0.07755767553445171,5620.801067702584,8.064455741363117
453.9316547780121,0.0814238187127165,490.8925035446204,0.07827852353485115,5574.92465908036,8.14238187127166
454.5716184118103,0.08223573858221787,491.95365119041963,0.0790290296899198,5527.665054741831,8.223573858221794
455.16331819950506,0.0829496827404712,492.91897103925413,0.07968850594271319,5487.221929752248,8.294968274047118
455.8124482226795,0.0837637391519624,493.99300323782137,0.08043992645044577,5441.643995807711,8.376373915196233
456.39629110519456,0.0845708094102805,494.99409485581083,0.08118434137121829,5396.6172759570945,8.45708094102804
456.98481071698325,0.08529947196890822,495.9653737689534,0.08185595993963755,5357.416642433084,8.52994719689082
457.56191910934444,0.08613750512939645,496.97516126364206,0.08262782963784567,5311.994100850625,8.61375051293964
458.11676627036326,0.08691917427739099,497.93589731721175,0.08334724868394391,5270.606515523773,8.6919174277391
458.7209996925112,0.08770108081893994,498.9513271598891,0.08406636879092581,5230.505660922775,8.770108081894003
459.2558304522391,0.08848532738266823,499.89323296220465,0.0847871219347952,5190.191911322399,8.848532738266828
459.8054396764715,0.08926333388725163,500.84920616148696,0.08550162728751912,5151.11210452044,8.926333388725173
460.36758253515717,0.09010811580735853,501.85043797618874,0.08627688013625749,5109.057917927988,9.010811580735842
460.8700503283118,0.09090385900179403,502.76491640150635,0.08700658106310726,5069.862329158284,9.090385900179404
461.40750005643287,0.09168176376628266,503.7101534765977,0.08771940972770853,5032.707499308847,9.168176376628251
461.88733247990336,0.09256327386059574,504.6411361289807,0.08852656288771227,4989.963224242971,9.256327386059573
462.4058882217591,0.09337326066829678,505.58223375724475,0.0892676519650738,4952.230273551545,9.33732606682969
462.9048017006658,0.09421933129627055,506.5193825707352,0.0900411695508136,4913.055477384701,9.421933129627044
463.3599409935716,0.09498055068521954,507.37012335461185,0.09073660117941278,4878.471830819545,9.498055068521944
463.87138810693153,0.09579945670789401,508.3100150699122,0.09148419432710551,4842.108755599111,9.579945670789396
464.29304201823857,0.0965908250782551,509.13949002487317,0.09220611725415509,4806.802733510991,9.659082507825504
464.75903132305916,0.09738229518871093,510.0183325029806,0.09292761209607293,4772.52082036506,9.738229518871085
465.23306460223034,0.098255530421984,510.94478613456766,0.09372303952871157,4734.930060467494,9.825553042198406
465.6341409047335,0.09904818750021196,511.7543585995657,0.09444452113923864,4701.086942188993,9.904818750021207
466.1300612769051,0.09984911943947991,512.672737439675,0.09517300625053578,4668.3442367204225,9.984911943948005
466.53469189365615,0.10066412542518882,513.4979986336409,0.09591374800692087,4634.567577308101,10.06641254251887
466.97804582879263,0.1014851001631233,514.3693595837073,0.0966593603082394,4601.444399997535,10.148510016312335
467.3802445463214,0.10230505750011024,515.1956073390485,0.0974034941106092,4568.4959860935305,10.230505750011035
467.7816949871665,0.10313145837643158,516.024703392992,0.09815291574124779,4535.780860188705,10.313145837643154
468.2128894261916,0.10394585392157195,516.8816780346837,0.09889090129124546,4504.392159589765,10.394585392157195
468.5958200191132,0.10481440911048635,517.7114140060604,0.09967736530748128,4470.719474506217,10.481440911048644
468.97557043612886,0.1056643797754257,518.5295832160889,0.1004464029576987,4438.350666827065,10.566437977542572
469.36149413578556,0.1065053973120267,519.3510265516838,0.10120675832086351,4406.926841094322,10.65053973120266
469.72104108233924,0.10729483262058745,520.1196815636368,0.10191995306296242,4377.853337479464,10.72948326205873
470.1045328827737,0.10817050961613463,520.9559797775582,0.10271046603055861,4345.958381365093,10.817050961613461
470.4384513529081,0.10896265799388882,521.6986754348496,0.10342503601943706,4317.428190667785,10.896265799388864
470.80978365723126,0.10984403243474221,522.5254288038702,0.1042194941315504,4286.166241547414,10.98440324347424
471.16895646544305,0.11071818332886808,523.3359273662555,0.10500681811020413,4255.569792596054,11.07181833288683
471.4750016291068,0.11158806113901427,524.0859829364125,0.10578967857935724,4225.138395780103,11.158806113901438
471.87439430907153,0.1124294856359943,524.9269897460367,0.10654634935144401,4197.069760123504,11.242948563599414
472.18418085615417,0.11324968036653565,525.6588884122481,0.10728337810221665,4169.40850806746,11.324968036653562
472.42082335739786,0.1140419304843846,526.2966060540979,0.10799478036979741,4142.518645123119,11.40419304843844
472.7966453218237,0.11495579392882942,527.1473590516812,0.10881475742552951,4112.856161165205,11.495579392882957
473.084170637564,0.11579063923301534,527.8628891667084,0.10956324710660759,4085.6858012981215,11.579063923301534
473.4525098351521,0.11665882137491564,528.6849216095166,0.11034103150978151,4058.4372810829327,11.66588213749155
473.7258178939007,0.11748756227341633,529.3827094242355,0.11108291748697405,4032.13590210893,11.748756227341646
474.0243802907268,0.11832898677039634,530.1152049149936,0.11183559510452154,4005.9869794247124,11.832898677039639
474.31003491475775,0.1191529458844436,530.8254728374044,0.11257210085169012,3980.682402722557,11.91529458844435
474.5708093390532,0.12000172958161083,531.5201272686845,0.11333022957510626,3954.699744692487,12.000172958161096
474.8749838110075,0.12091104863515663,532.2926160741994,0.11414179092840276,3927.473867536459,12.09110486351565
475.1320168518841,0.12170265439907213,532.9568444927431,0.11484775807354415,3904.03988473325,12.17026543990723
475.4167361300603,0.12257514353831703,533.6910108017207,0.11562528141223374,3878.573766315394,12.257514353831718
475.68143900694554,0.12347154159982908,534.4145595915581,0.11642348219322057,3852.5593253595857,12.347154159982903
475.919016854044,0.12431462785169008,535.0827123217966,0.11717363031927824,3828.3428513483163,12.431462785168995
476.19494388118585,0.12520522672780118,535.8170397964623,0.11796544277723854,3803.315215557604,12.520522672780116
476.4416881176605,0.12605295911065592,536.4985727485678,0.11871856156943743,3779.694594074661,12.605295911065584
476.6579400792714,0.12698208356931384,537.1849584603945,0.11954333747724841,3753.741682928719,12.698208356931392
476.92750675460115,0.12779542780014178,537.8766615099604,0.12026477829524845,3731.9606418193944,12.779542780014175
477.1512414830497,0.12866157514014698,538.5422717923356,0.1210324839341476,3708.5760916831928,12.866157514014704
477.4030365871399,0.1295626193326528,539.2566244847321,0.12183049525873475,3684.728195880362,12.956261933265298
477.62639717724664,0.1304145230593925,539.9158159656932,0.12258440002273407,3662.3712296193366,13.041452305939249
477.8415267238318,0.13126422241741248,540.5650231679848,0.12333578825565321,3640.302878604072,13.126422241741246
478.04823815772454,0.132172015369537,541.2328372388873,0.1241379252769166,3616.864256939409,13.217201536953688
478.24896337814704,0.13302608955163142,541.8685528084634,0.12489200874600566,3595.151635217573,13.302608955163157
478.4710144840572,0.13387850197884485,542.527997143481,0.12564405845341164,3573.9196914502677,13.387850197884493
478.66612762935137,0.134799249836368,543.189962555867,0.12645576289873475,3550.9554260161035,13.479924983636787
478.9046408223045,0.1356687206861352,543.8770207733196,0.1272216586555196,3529.956193294057,13.566872068613517
479.08216946553006,0.13648854236966249,544.4713964511759,0.1279432827547257,3510.0541125862032,13.648854236966255
479.25726620953327,0.13741739552140103,545.1155515167541,0.1287602498842126,3487.602602211268,13.741739552140098
479.4636035050841,0.13829466644509936,545.770862624385,0.12953123579391126,3466.9710396635073,13.829466644509921
479.6317786897625,0.13921059860480417,546.4016057110513,0.13033556518286202,3445.3682657550926,13.921059860480417
479.82071855241554,0.14005290484927205,547.0210039925463,0.1310746690921165,3425.996191002314,14.005290484927196
480.00928427672676,0.14093146448083727,547.6576956742445,0.13184500288907197,3405.976699702816,14.093146448083738
480.1664223803194,0.14180341100624347,548.2556589245132,0.13260895193736172,3386.141553105363,14.18034110062433
480.33777774090373,0.14265738344824314,548.8615082847648,0.1333565878642735,3367.0726753177332,14.265738344824308
480.4861235934621,0.1435771817315486,549.4729670801279,0.13416122825152063,3346.5354159955878,14.357718173154854
480.6565436081917,0.14443698727231416,550.0811266796826,0.1349128019024938,3327.7940275920205,14.44369872723141
480.8260282770667,0.14538371276736448,550.7303014631725,0.13573970118677275,3307.289510802766,14.538371276736461
480.9545447975049,0.14627648209883035,551.3068836599282,0.1365188475703685,3287.9827153113542,14.627648209883024
481.1343182707818,0.14716019656186308,551.9381391201681,0.13728949409834257,3269.4596060050994,14.716019656186315
481.25722271609175,0.14805723897730858,552.5108383493239,0.13807115639075077,3250.480868347476,14.805723897730841
481.3930349341968,0.14895570575408065,553.0992741979189,0.13885344786599324,3231.7864730133642,14.895570575408074
481.5526049370118,0.14985393513729825,553.7151577624397,0.13963492138424574,3213.479876226184,14.98539351372982
481.6427722774066,0.15076739162136407,554.2587967469539,0.14042901689352624,3194.6083771681883,15.076739162136409
481.8143147071619,0.15163367461482896,554.8735897282345,0.14118152091817013,3177.4888785821395,15.163367461482903
481.9321682848564,0.15251196293947483,555.4325892736572,0.14194387582566237,3159.963054676004,15.251196293947485
482.04160374985844,0.15338818254886066,555.9810892619872,0.14270385639400857,3142.625433978968,15.338818254886055
482.1809702822115,0.15432259749244578,556.5923900775902,0.14351367624035424,3124.500093421604,15.432259749244572
482.2862902254527,0.15525989507204896,557.1660090405443,0.14432533603954106,3106.3159613862026,15.525989507204901
482.4452990207548,0.15618861257032784,557.7977609158835,0.1451289166040089,3088.8634650206764,15.61886125703279
482.5339698077821,0.1571654870467903,558.3716561892434,0.14597346913895254,3070.228578009148,15.716548704679024
482.6385414743396,0.1580604607469758,558.9246117140221,0.1467465891410125,3053.5058495555727,15.806046074697589
482.74891228519635,0.158930745517501,559.4725568124453,0.14749780892043995,3037.479694147898,15.8930745517501
482.82804254450554,0.1598870345814582,560.0259864797167,0.14832261639464397,3019.8073521622387,15.988703458145832
482.949263367277,0.1608162946935758,560.6153744269944,0.1491234599579382,3003.111496179557,16.08162946935759
483.005758256902,0.16175888275810615,561.1362300782705,0.14993513496887495,2985.961265442144,16.175888275810635
483.11107820014325,0.16265941825013822,561.6936451303756,0.15070998305598332,2970.0774993379932,16.265941825013815
483.2207007343162,0.16360458373040232,562.2778223278673,0.1515225868975672,2953.5890114826916,16.360458373040224
483.2771956239412,0.16450189745276717,562.7772112997317,0.15229343975507217,2937.8214057543187,16.45018974527671
483.4068345594052,0.1654140652289661,563.3691242233427,0.1530764446680502,2922.4046570058817,16.541406522896626
483.45977513478215,0.16633542352705777,563.8762615901222,0.15386671682248687,2906.5352700180415,16.63354235270577
483.5473235067838,0.1672988683110127,564.4442435042879,0.1546924201831746,2890.3203493753313,16.729886831101272
483.6015735663575,0.16821154478768538,564.9489413177099,0.15547398511905547,2874.9606584777143,16.821154478768523
483.6765883039059,0.16910058364901026,565.4665816834585,0.15623472125984206,2860.28928976282,16.910058364901037
483.7841530771984,0.17008481732565986,566.0684923783829,0.15707623962287726,2844.370007176486,17.008481732566004
483.81595483625887,0.17101743486090434,566.556918377135,0.15787297336973316,2829.0446247762206,17.10174348609044
483.8825514611148,0.1719253634664885,567.0742349961588,0.15864800607789822,2814.491949906115,17.192536346648847
483.9463420484066,0.17292706252607093,567.6337613990748,0.15950238745338494,2798.5575824804496,17.292706252607115
483.95494723027,0.17381233700388987,568.0722876129576,0.1602568593985782,2784.3532603755234,17.381233700389007
484.0056429755957,0.17481352736299852,568.6163766877557,0.16110943488532928,2768.696738042262,17.48135273629986
484.0660663178105,0.175712638493704,569.1225920357813,0.16187446459452184,2754.8733572466112,17.571263849370396
484.1205034465552,0.17667489630988678,569.6524431944655,0.16269257628370282,2740.1770911324634,17.667489630988676
484.1689543618295,0.177601816399825,570.1582401008943,0.16348001145037566,2726.148663208754,17.760181639982488
484.20973544109523,0.17853714700426293,570.6591601584373,0.1642739634779076,2712.0951777589107,17.853714700426295
484.2546320421217,0.17948322814537984,571.1702166453948,0.16507640030318085,2698.049489336573,17.94832281453798
484.29541312138747,0.18046539310676946,571.693975230144,0.16590876165990762,2683.591600495181,18.046539310676955
484.3313304022086,0.18138352963519394,572.1810566234706,0.16668623439817826,2670.20567620619,18.138352963519406
484.3706149281068,0.18236959463354913,572.7050876249485,0.16752055592307058,2655.9833940597073,18.236959463354903
484.39231495193627,0.18334918217920504,573.2052497522657,0.16834870812040156,2641.9115111104907,18.3349182179205
484.4228072268001,0.18426575869284326,573.6853433285634,0.16912296963024817,2628.935569273591,18.426575869284324
484.44170121306536,0.18519668055984184,574.1586962024877,0.16990873597072678,2615.8228092891204,18.51966805598417
484.46639434362993,0.18619722656501703,574.6726933343676,0.17075258233597312,2601.8990899118585,18.619722656501693
484.4888426441432,0.18712909800623329,575.1508027622256,0.17153786961775747,2589.062031539343,18.712909800623326
484.50137627859635,0.18811590909861667,575.6437931367755,0.172368782762471,2575.5470581948734,18.811590909861668
484.50624007704096,0.18906819638551356,576.1109610259338,0.17316997214922472,2562.600423231011,18.906819638551365
484.5176512964685,0.1900382203622626,576.5945234829527,0.17398542455914884,2549.58002854821,19.00382203622626
484.5307461384345,0.19097199095191425,577.0625474059079,0.1747697728438274,2537.1822523462974,19.09719909519144
484.5372935594176,0.19196348208865635,577.550759632897,0.17560193234220728,2524.1118169321344,19.196348208865654
484.5387901127851,0.1929347947732722,578.0231821428849,0.1764164851034253,2511.4121622395382,19.29347947732723
484.53972545863985,0.1939166884277425,578.5000644312669,0.17723923734986355,2498.7004954923705,19.391668842774266
484.5417832195202,0.1948903411345377,578.9742966451097,0.17805441643185996,2486.2277955839218,19.48903411345377
484.5408478736655,0.19585775378218803,579.4419299539185,0.17886371349039043,2473.9426370248266,19.585775378218802
484.52812717004133,0.19682387772197146,579.8948320250134,0.17967127934417437,2461.734484544979,19.682387772197156
484.5176512964685,0.19782934116505976,580.369459035291,0.1805110364282023,2449.169816989933,19.782934116505974
484.5019374861092,0.1988434525162021,580.8419754866363,0.1813573024803215,2436.599904875576,19.884345251620214
484.482856430673,0.1997947224021515,581.2799742398407,0.18215047749585223,2424.9031736458714,19.97947224021515
484.4648977902624,0.2007970658156673,581.7440277572342,0.18298555780953552,2412.7090494190966,20.079706581566725
484.4452555273133,0.2017212728364121,582.1681690918439,0.1837549230638725,2401.5575983410486,20.17212728364122
484.40709341644083,0.20278018374261111,582.6352528256509,0.1846356968906106,2388.8285555125976,20.27801837426112
484.3771623490898,0.2037714035724339,583.0793765793965,0.18545946471765443,2377.06152019957,20.377140357243377
484.3373166156788,0.2047720852310687,583.5160788942916,0.18629040816614495,2365.2506935656947,20.477208523106853
484.30457951076363,0.20575269017767212,583.9515496104696,0.18710401108837982,2353.8189420150748,20.575269017767212
484.2682880916006,0.2067429943466421,584.3873640387804,0.18792499015246297,2342.368550973181,20.674299434664213
484.2174052771039,0.20774432035921037,584.8108210424962,0.18875442177869295,2330.8334227373552,20.77443203592103
484.1710121227099,0.2086783622557814,585.207025984201,0.18952750005660354,2320.1783207846506,20.86783622557812
484.1270508675382,0.20975860466851384,585.6768655397956,0.1904208394318674,2308.0199815050014,20.97586046685138
484.0731749463064,0.21074619576829035,586.0897550397185,0.1912368602506657,2296.94857922148,21.074619576829033
484.0101326356984,0.21176549586426516,586.5067783766259,0.19207838366592758,2285.5948777695744,21.17654958642653
483.9440972183553,0.2127743167304803,586.91497183974,0.19291055884341346,2274.4478969769825,21.27743167304804
483.88479629116614,0.21381057350891416,587.3444820984245,0.1937646454616849,2263.1471790659225,21.381057350891414
483.8152065595751,0.21480891514536965,587.7430262114704,0.1945867929387624,2252.305060207386,21.48089151453697
483.7386952686591,0.2158367614093038,588.1472886238085,0.1954325322705906,2241.2247668566397,21.58367614093037
483.6554494875893,0.21689136531815825,588.5561402705201,0.19629954569747646,2229.94331184238,21.68913653181584
483.56958473812614,0.21785826926533478,588.9192175385309,0.1970937990237918,2219.6521911645928,21.78582692653347
483.47885619021844,0.2188711258219752,589.2984177556923,0.1979251236813549,2208.9659125867024,21.887112582197503
483.3718526244387,0.21987618230468448,589.6538102130428,0.19874936368052226,2198.3820510155383,21.98761823046843
483.2820594223857,0.22087879702511964,590.0288193314246,0.19957092486574574,2187.9966114059557,22.087879702511962
483.1771136174864,0.22193831837188718,590.4126296895337,0.20043838351136353,2177.0783754784466,22.19383183718874
482.98237461053407,0.22295880543563415,590.6675479001647,0.20127317292894048,2166.240412289821,22.295880543563406
482.88771761003653,0.22394924525806376,591.0300575131932,0.20208271693795235,2156.2373074916586,22.394924525806374
482.7511571152477,0.22503671121752372,591.3878898489171,0.2029708118884843,2145.210683640917,22.503671121752372
482.63610957511736,0.22608188721093098,591.7513920640015,0.20382362746209476,2134.7845045402737,22.608188721093082
482.48308699328544,0.22714944602518408,592.078852920331,0.2046939562135478,2124.0777621786165,22.714944602518415
482.32276871378673,0.2281921802563172,592.3850528938491,0.20554331606038825,2113.669137005558,22.81921802563171
482.1865823573398,0.22920344288480646,592.7054071465003,0.2063663521853419,2103.7492992619577,22.920344288480642
482.00082267059275,0.2302364778935731,592.9749944240747,0.2072064093550982,2093.5032844508587,23.023647789357298
481.85565699394044,0.231371931264392,593.343530943301,0.2081289390695102,2082.6020440799152,23.137193126439215
481.657924880253,0.23243029955675232,593.6098206440539,0.2089880732518077,2072.268227502099,23.243029955675233
481.4646824266683,0.23345892582807962,593.8669100101557,0.20982235755006517,2062.310021854643,23.34589258280796
481.28322533085293,0.23456721459359922,594.1764909273347,0.21072047513631337,2051.7923878010956,23.456721459359933
481.05051128219907,0.23561615497051233,594.3937830971098,0.21156975657257068,2041.6703232526784,23.561615497051218
480.83500759727195,0.23667516761680613,594.6367136163846,0.21242646201127843,2031.6242402573384,23.667516761680616
480.6333470309947,0.23775890310612513,594.9082044173095,0.2133024082095916,2021.5156646161893,23.77589031061251
480.3594777647332,0.2388630544411247,595.0996098533609,0.21419406743500552,2011.024596870559,23.886305444112473
480.12994389198536,0.23991352091945917,595.3196092299739,0.21504163599093082,2001.2625468206468,23.991352091945913
479.85551341821105,0.24099559465389717,595.4985782223839,0.21591395638047012,1991.1381123266988,24.09955946538971
479.59137174883864,0.24204385676351195,595.6735170374308,0.2167582942916479,1981.4234418575704,24.204385676351198
479.3059041939786,0.243153196843344,595.8506670646341,0.21765105259578507,1971.209551905585,24.315319684334398
478.9934986785027,0.24425890819312984,595.9919276973212,0.2185400982190469,1961.0072861693693,24.425890819312997
478.700548356805,0.24531832779980264,596.1345663965449,0.2193911822145983,1951.3444129924894,24.53183277998025
478.3640109182774,0.2464421488864547,596.2530657189212,0.22029321206326757,1941.0803431140264,24.64421488864548
478.01250794607427,0.24751903387606022,596.3297020935591,0.22115680614322078,1931.2151492374871,24.751903387606028
477.65988255884554,0.24862966266375916,596.4202980274621,0.22204668010187437,1921.1701348958568,24.862966266375906
477.2674114382058,0.2497342209591378,596.4574166229104,0.2229309054739958,1911.1013685076728,24.973422095913776
476.9022524165238,0.2508573976918564,596.5367104111178,0.22382923433335405,1901.0890522046006,25.085739769185643
476.4940674855248,0.25191125550668264,596.5282862672893,0.22467138798248534,1891.5155915805615,25.191125550668268
476.0727877125597,0.25306224119863396,596.5488343447815,0.22559034842215825,1881.2478126236147,25.30622411986339
475.6647898507316,0.2548031498733336,596.8656765885353,0.22697870759050665,1866.7932091388652,25.48031498733335
475.20216779098797,0.2552923162489105,596.5176298928527,0.2273684667756623,1861.4041142063395,25.529231624891054
474.7629293776123,0.25645506987848843,596.5182896068637,0.22829431920736748,1851.2518766057572,25.645506987848844
474.26251934533803,0.25757865357158605,596.4224205177785,0.2291881686075772,1841.2337853669671,25.75786535715861
473.74489894933697,0.25868087184478533,596.2936424415711,0.23006424544509171,1831.3874372342273,25.868087184478522
473.25103633804576,0.2598170034829026,596.209702494575,0.23096647508468499,1821.478309710351,25.981700348290254
472.71452195577945,0.26093526277770807,596.0624099611493,0.23185371766153842,1811.6160955925957,26.093526277770795
472.1684670457949,0.2620537933794329,595.9020049492972,0.2327403887093389,1801.7997791855382,26.205379337943285
471.60071211198095,0.2632135965462629,595.7324316807542,0.23365894747504085,1791.7034617514203,26.321359654626292
471.0095735317991,0.2643215122647684,595.5075362989079,0.2345356243493614,1781.957017028539,26.43215122647684
470.41001683892466,0.2654498438289546,595.2802823443931,0.23542766673595075,1772.1239163434518,26.544984382895446
469.7887601222208,0.26664186469245665,595.054111132767,0.23636919736657452,1761.8717175717052,26.664186469245678
469.1759215182095,0.26777023017000773,594.807266013366,0.2372596331046243,1752.1586369789093,26.777023017000772
468.50789750876976,0.2688918468879401,594.4858513514887,0.23814395806156,1742.3655753460575,26.88918468879403
467.84361488274885,0.27009526264205463,594.2059589199132,0.23909190761176777,1732.1429865386474,27.00952626420547
467.162683100514,0.2712353621438673,593.8737226313826,0.23998915377657562,1722.3516852965652,27.12353621438673
466.4615478478172,0.2724175481315432,593.5338590101641,0.2409186721617438,1712.303598087504,27.241754813154316
465.76190914848803,0.27356209028416006,593.1767105898895,0.2418177698704991,1702.5820670718015,27.356209028416007
464.97996001394364,0.2747200621292845,592.7192835178464,0.2427265953894718,1692.5591688135319,27.47200621292844
464.22644539338256,0.2758919045406604,592.3027635511038,0.2436454670243111,1682.6388804930148,27.58919045406605
463.46021006919744,0.2770622886773449,591.8675565818523,0.24456235321191822,1672.7653997290254,27.706228867734488
462.6445884838832,0.27821276566882247,591.3582189676986,0.2454628254074727,1662.9164638498428,27.821276566882247
461.8622652109969,0.2794147570616104,590.9133978408527,0.24640275232849482,1652.963036269259,27.94147570616104
460.99258063527986,0.2805878542674883,590.3414996689651,0.24731923364987876,1642.9527280814132,28.058785426748816
460.1449702217342,0.2817137779827652,589.7741482026659,0.24819807146785727,1633.3775845705534,28.17137779827651
459.27435030016255,0.2828897239112962,589.1983444561155,0.24911513019453874,1623.5101931244915,28.28897239112962
458.3745475879236,0.283982242962129,588.5447797286932,0.24996637570339458,1614.0958068601883,28.39822429621289
457.50748198059983,0.2851007735638538,587.9432190045197,0.25083713827915,1604.7219944779708,28.510077356385377
456.54538523443665,0.286179862922179,587.1994809985812,0.2516764783390127,1595.3092596126696,28.61798629221791
455.6163997315306,0.2875638334311169,586.6351982124137,0.25275193169071253,1584.4009112525237,28.756383343111708
454.64120814340134,0.28853748613791214,585.8222394358016,0.2535078435376273,1575.6746696202124,28.853748613791215
453.6491803298872,0.2897232669422693,585.0819029007448,0.25442767361032004,1565.8016876507265,28.972326694226936
452.65490768632174,0.29089198932407273,584.3285942605004,0.2553334440143886,1556.09272272546,29.089198932407278
451.61180998914,0.2920927937490886,583.5243652589504,0.2562632245685692,1546.1244496743054,29.209279374908846
450.54888295983824,0.29329787125808415,582.6939112296666,0.2571954454608139,1536.1478111901563,29.329787125808434
449.50054732587006,0.29448755209940686,581.8728631752091,0.2581149041720331,1526.3821649552685,29.44875520994068
448.40413491496935,0.2957032444916217,580.9986924527847,0.25905359369489056,1516.3991037226315,29.57032444916217
447.31632768593204,0.29695888682770993,580.1508864154056,0.26002220616397514,1506.3240991520038,29.695888682771006
446.1471453675343,0.29822941713099715,579.2013484851523,0.26100134929810237,1495.986377398727,29.82294171309971
445.00265617970115,0.29939841081971996,578.235744250458,0.26190139645270993,1486.322706127039,29.939841081972013
443.8329126537905,0.30056028270180996,577.2314583533815,0.26279515831310246,1476.6851716536457,30.056028270180995
442.60442940820366,0.301780858618573,576.173974143395,0.26373321826756974,1466.6418255758906,30.178085861857305
441.424771216233,0.3029765082121213,575.1661070376618,0.2646512689795094,1456.9603888469817,30.29765082121214
440.1626155198762,0.3041479436631182,574.0371699076263,0.26554991079845874,1447.1990512860782,30.414794366311824
438.9042012069384,0.30531419036928265,572.9078820481116,0.26644377070054776,1437.5493018391198,30.53141903692827
437.6096825440084,0.3065305271154309,571.7504092050397,0.2673751712742015,1427.6218641649898,30.653052711543076
436.29439920310364,0.30772563409514053,570.553369850037,0.26828947116622875,1417.8032339945169,30.772563409514042
434.98472793732725,0.3089203680278361,569.3603701782146,0.2692026508739539,1408.0804406465415,30.89203680278362
433.6116402226009,0.3101069627529513,568.0776289863571,0.27010878483625367,1398.2647676570887,31.010696275295135
432.2248964583956,0.3113025784331347,566.7776211888888,0.27102097787156854,1388.4398215841763,31.130257843313462
430.81196301025835,0.3125006697889572,565.4409900040596,0.2719342257989075,1378.5953268554624,31.25006697889573
429.38743127352245,0.3136646103863071,564.0710726087091,0.2728206442451104,1368.9380856344997,31.366461038630707
427.9331555386066,0.3149035673468557,562.6908328037107,0.2737633301246661,1358.933971895125,31.490356734685566
426.4395952777926,0.3161019300095975,561.2379743776145,0.27467428431827495,1349.057233737374,31.610193000959754
424.93593328174757,0.31728408208390846,559.7613408175158,0.27557210343654404,1339.291686146958,31.728408208390846
423.38924537638553,0.31851761290607017,558.2461771437743,0.27650808501251806,1329.2490845749296,31.851761290607023
421.8202962396812,0.31968246916427295,556.6688500851876,0.2773911539971767,1319.4977420639336,31.968246916427294
420.25658503976337,0.32091640694681367,555.1238183064622,0.27832574340681376,1309.5515715075721,32.09164069468136
418.6025194302797,0.32211538005012397,553.4408290665036,0.2792330145122562,1299.5421682911926,32.21153800501239
416.96341935447145,0.3232961416764733,551.7660840520014,0.2801257011094552,1289.7259373164195,32.32961416764732
415.308605468304,0.32451261407608123,550.0814866771152,0.2810445533358881,1279.7918708051695,32.45126140760812
413.5961742774859,0.32573162997805805,548.3175302775803,0.28196448061480156,1269.745201917746,32.5731629978058
411.8740154897788,0.32692144647284055,546.5244643982744,0.2828615572699714,1259.8562129633665,32.69214464728405
410.1043411326519,0.3281355788502691,544.6741664992228,0.2837761383508895,1249.8015075646088,32.8135578850269
408.28958310532767,0.32932566665197094,542.7498222485449,0.2846717961018904,1239.774558892202,32.93256666519707
406.47763111556753,0.33057717155753913,540.8498567111607,0.2856128116757995,1229.5998214287383,33.05771715575393
404.61666700302015,0.3317425365162157,538.845226431339,0.2864882625313611,1219.6707460312143,33.17425365162157
402.75645116715657,0.3329469696712778,536.8529910988193,0.28739225771300453,1209.6714728018171,33.29469696712778
400.80120419245367,0.3341859266318264,534.7433260106607,0.28832131306782577,1199.3359751322428,33.418592663182636
398.81378132034837,0.3354127426077343,532.5810055027675,0.2892404145615495,1189.02394172532,33.54127426077341
396.8308481083458,0.33661069831009705,530.4083570010841,0.2901370801852727,1178.9014731277848,33.66106983100971
394.7818794790001,0.3378781085838118,528.170034220527,0.2910848578430607,1168.4150865343001,33.78781085838117
392.71382979421816,0.33903170560486184,525.8562693239694,0.2919467449984277,1158.3395396415292,33.903170560486195
390.62875681488026,0.3402551641576429,523.5422085896233,0.29286001684820656,1148.046519093826,34.025516415764294
388.4617475386691,0.3414350101231394,521.096188241987,0.2937399440321435,1137.7326168121112,34.14350101231393
386.2866942881074,0.3427311789303047,518.6791884265607,0.29470573289663426,1127.08360964924,34.27311789303048
384.0336331932622,0.34396189494317814,516.12656938833,0.29562188972223097,1116.5005160141468,34.39618949431782
381.7798238217332,0.34515801932383533,513.5541916298454,0.2965114926389286,1106.1015605827151,34.51580193238352
379.44052383908297,0.34635685677368594,510.86235100854856,0.2974023199865889,1095.5190186606133,34.635685677368585
377.05221173364544,0.3475665465003103,508.1029468162124,0.2983004077395382,1084.8345893188796,34.756654650031045
374.6431349502333,0.3488688197131608,505.3444432539596,0.29926632988283924,1073.8796756278307,34.88688197131608
372.13360202202426,0.35009580525589334,502.416015084701,0.30017555678852714,1062.9479029319502,35.00958052558933
369.6139673585844,0.35136111290098315,499.4819422734442,0.30111231630455937,1051.9489886256852,35.1361112900983
366.9923799969802,0.3525328196588994,496.36923851064597,0.3019789973656391,1041.016210496576,35.253281965889954
364.3300115561103,0.3538005012395335,493.2301522612672,0.30291582333867006,1029.7611514955092,35.38005012395336
361.5888869942731,0.3550559740087971,489.97318145678156,0.30384276271004595,1018.3996706539406,35.50559740087971
358.7456226651007,0.3562459939837691,486.54731359875564,0.3047205845575839,1007.0165804627841,35.6245993983769
355.88982470147505,0.3575336844497048,483.13242498515297,0.30566958610904416,995.4022241267704,35.75336844497048
352.81104028608456,0.35878542674882746,479.3944999368252,0.30659123215760153,983.3483023073695,35.87854267488275
343.4145558295854,0.35993644635414374,467.02197068117306,0.30743796803409795,954.0977561680367,35.99364463541436